<?xml version='1.0'?>

<robot xmlns:xacro="http://www.ros.org/wiki/xacro">
	<xacro:property name="robot_chassis_mass" value="15" />
	<xacro:property name="robot_chassis_length" value="0.2" />
	<xacro:property name="robot_chassis_radius" value="0.25" />
	<xacro:property name="robot_caster_wheel_radius" value="0.05" />
	<xacro:property name="robot_caster_wheel_radius_collision" value="0.0499" />

	<xacro:property name="robot_wheel_mass" value="5" />
	<xacro:property name="robot_wheel_length" value="0.05" />
	<xacro:property name="robot_wheel_radius" value="0.1" />

	<link
		name="base_link">
	</link>


	<joint name="chassis_joint" type="fixed">
		<parent link="base_link" />
		<child link="chassis" />
		<origin xyz="0 0 0" rpy="0 0 0" />
	</joint>

	<!-- Make Chassis of Bot -->
	<link name="chassis">
		<pose>0 0 0.1 0 0 0</pose>

		<inertial>
			<mass value="${robot_chassis_mass}" />
			<origin xyz="0.0 0 0" rpy=" 0 0 0" />

			<inertia
				ixx="0.147116667" ixy="0" ixz="0"
				iyy="0.334951167" iyz="0"
				izz="0.3978345"
			/>
		</inertial>

		<collision name="collision">
			<origin xyz="0 0 0.05" rpy=" 0 0 0" />
			<geometry>
				<box size="0.5 0.5 0.2" />
			</geometry>
		</collision>

		<visual name="chassis_visual">
			<origin xyz="0 0 0.05" rpy=" 0 0 0" />
			<geometry>
				<box size="0.5 0.5 0.2" />
			</geometry>

		</visual>

	</link>


	<!-- Right Wheel Back -->
	<link name="right_rear_link">
		<inertial>
			<mass value="${robot_wheel_mass}" />
			<origin xyz="0 0 0" rpy="0 1.5707 1.5707" />
			<inertia
				ixx="0.1" ixy="0.0" ixz="0.0"
				iyy="0.1" iyz="0.0"
				izz="0.1"
			/>
		</inertial>

		<visual>
			<origin xyz="0 0 0" rpy="0 1.5707 1.5707" />
			<geometry>
				<cylinder radius="${robot_wheel_radius}" length="${robot_wheel_length}" />
			</geometry>
		</visual>

		<collision>
			<origin xyz="0 0 0" rpy="0 1.5707 1.5707" />
			<geometry>
				<cylinder radius="${robot_wheel_radius}" length="${robot_wheel_length}" />
			</geometry>
		</collision>

	</link>

	<!-- Right Wheel Front-->
	<link name="right_front_link">
		<inertial>
			<mass value="${robot_wheel_mass}" />
			<origin xyz="0 0 0" rpy="0 1.5707 1.5707" />
			<inertia
				ixx="0.1" ixy="0.0" ixz="0.0"
				iyy="0.1" iyz="0.0"
				izz="0.1"
			/>
		</inertial>

		<visual>
			<origin xyz="0 0 0" rpy="0 1.5707 1.5707" />
			<geometry>
				<cylinder radius="${robot_wheel_radius}" length="${robot_wheel_length}" />
			</geometry>
		</visual>

		<collision>
			<origin xyz="0 0 0" rpy="0 1.5707 1.5707" />
			<geometry>
				<cylinder radius="${robot_wheel_radius}" length="${robot_wheel_length}" />
			</geometry>
		</collision>

	</link>


	<!-- Left wheel Back-->
	<link name="left_rear_link">
		<inertial>
			<mass value="${robot_wheel_mass}" />
			<origin xyz="0 0 0" rpy="0 1.5707 1.5707" />
			<inertia
				ixx="0.1" ixy="0.0" ixz="0.0"
				iyy="0.1" iyz="0.0"
				izz="0.1"
			/>
		</inertial>

		<visual>
			<origin xyz="0 0 0" rpy="0 1.5707 1.5707" />
			<geometry>
				<cylinder radius="${robot_wheel_radius}" length="${robot_wheel_length}" />
			</geometry>
		</visual>

		<collision>
			<origin xyz="0 0 0" rpy="0 1.5707 1.5707" />
			<geometry>
				<cylinder radius="${robot_wheel_radius}" length="${robot_wheel_length}" />
			</geometry>
		</collision>

	</link>

	<!-- Left wheel Front-->
	<link name="left_front_link">
		<inertial>
			<mass value="${robot_wheel_mass}" />
			<origin xyz="0 0 0" rpy="0 1.5707 1.5707" />
			<inertia
				ixx="0.1" ixy="0.0" ixz="0.0"
				iyy="0.1" iyz="0.0"
				izz="0.1"
			/>
		</inertial>

		<visual>
			<origin xyz="0 0 0" rpy="0 1.5707 1.5707" />
			<geometry>
				<cylinder radius="${robot_wheel_radius}" length="${robot_wheel_length}" />
			</geometry>
		</visual>

		<collision>
			<origin xyz="0 0 0" rpy="0 1.5707 1.5707" />
			<geometry>
				<cylinder radius="${robot_wheel_radius}" length="${robot_wheel_length}" />
			</geometry>
		</collision>
	</link>

	<!-- Define Joints -->

	<!-- Right Wheel Joint Back-->
	<joint type="continuous" name="right_rear_joint">
		<origin xyz="-0.2 -0.30 0" rpy="0 0 0" />
		<parent link="chassis" />
		<child link="right_rear_link" />
		<axis xyz="0 1 0" rpy="0 0 0" />
		<limit effort="10000" velocity="1000" />
		<dynamics damping="1.0" friction="1.0" />
	</joint>

	<!-- Right Wheel Joint Front-->
	<joint type="continuous" name="right_front_joint">
		<origin xyz="0.2 -0.30 0" rpy="0 0 0" />
		<parent link="chassis" />
		<child link="right_front_link" />
		<axis xyz="0 1 0" rpy="0 0 0" />
		<limit effort="10000" velocity="1000" />
		<dynamics damping="1.0" friction="1.0" />
	</joint>


	<!-- Left Wheel Joint Back-->
	<joint type="continuous" name="left_rear_joint">
		<origin xyz="-0.2 0.30 0" rpy="0 0 0" />
		<parent link="chassis" />
		<child link="left_rear_link" />
		<axis xyz="0 1 0" rpy="0 0 0" />
		<limit effort="10000" velocity="1000" />
		<dynamics damping="1.0" friction="1.0" />
	</joint>

	<!-- Left Wheel Joint Front-->
	<joint type="continuous" name="left_front_joint">
		<origin xyz="0.2 0.30 0" rpy="0 0 0" />
		<parent link="chassis" />
		<child link="left_front_link" />
		<axis xyz="0 1 0" rpy="0 0 0" />
		<limit effort="10000" velocity="1000" />
		<dynamics damping="1.0" friction="1.0" />
	</joint>

</robot>